/Users/s3nik/Desktop/nlp-project-3/midi_caption_project/venv/lib/python3.11/site-packages/huggingface_hub/file_download.py:795: FutureWarning: `resume_download` is deprecated and will be removed in version 1.0.0. Downloads always resume when possible. If you want to force a new download, use `force_download=True`.
  warnings.warn(
Error in training: your-base-model is not a local folder and is not a valid model identifier listed on 'https://huggingface.co/models'
If this is a private repository, make sure to pass a token having permission to this repo either by logging in with `huggingface-cli login` or by passing `token=<your_token>`
Traceback (most recent call last):
  File "/Users/s3nik/Desktop/nlp-project-3/midi_caption_project/venv/lib/python3.11/site-packages/huggingface_hub/utils/_http.py", line 406, in hf_raise_for_status
    response.raise_for_status()
  File "/Users/s3nik/Desktop/nlp-project-3/midi_caption_project/venv/lib/python3.11/site-packages/requests/models.py", line 1024, in raise_for_status
    raise HTTPError(http_error_msg, response=self)
requests.exceptions.HTTPError: 401 Client Error: Unauthorized for url: https://huggingface.co/your-base-model/resolve/main/config.json

The above exception was the direct cause of the following exception:

Traceback (most recent call last):
  File "/Users/s3nik/Desktop/nlp-project-3/midi_caption_project/venv/lib/python3.11/site-packages/transformers/utils/hub.py", line 389, in cached_file
    resolved_file = hf_hub_download(
                    ^^^^^^^^^^^^^^^^
  File "/Users/s3nik/Desktop/nlp-project-3/midi_caption_project/venv/lib/python3.11/site-packages/huggingface_hub/utils/_validators.py", line 114, in _inner_fn
    return fn(*args, **kwargs)
           ^^^^^^^^^^^^^^^^^^^
  File "/Users/s3nik/Desktop/nlp-project-3/midi_caption_project/venv/lib/python3.11/site-packages/huggingface_hub/file_download.py", line 860, in hf_hub_download
    return _hf_hub_download_to_cache_dir(
           ^^^^^^^^^^^^^^^^^^^^^^^^^^^^^^
  File "/Users/s3nik/Desktop/nlp-project-3/midi_caption_project/venv/lib/python3.11/site-packages/huggingface_hub/file_download.py", line 967, in _hf_hub_download_to_cache_dir
    _raise_on_head_call_error(head_call_error, force_download, local_files_only)
  File "/Users/s3nik/Desktop/nlp-project-3/midi_caption_project/venv/lib/python3.11/site-packages/huggingface_hub/file_download.py", line 1482, in _raise_on_head_call_error
    raise head_call_error
  File "/Users/s3nik/Desktop/nlp-project-3/midi_caption_project/venv/lib/python3.11/site-packages/huggingface_hub/file_download.py", line 1374, in _get_metadata_or_catch_error
    metadata = get_hf_file_metadata(
               ^^^^^^^^^^^^^^^^^^^^^
  File "/Users/s3nik/Desktop/nlp-project-3/midi_caption_project/venv/lib/python3.11/site-packages/huggingface_hub/utils/_validators.py", line 114, in _inner_fn
    return fn(*args, **kwargs)
           ^^^^^^^^^^^^^^^^^^^
  File "/Users/s3nik/Desktop/nlp-project-3/midi_caption_project/venv/lib/python3.11/site-packages/huggingface_hub/file_download.py", line 1294, in get_hf_file_metadata
    r = _request_wrapper(
        ^^^^^^^^^^^^^^^^^
  File "/Users/s3nik/Desktop/nlp-project-3/midi_caption_project/venv/lib/python3.11/site-packages/huggingface_hub/file_download.py", line 278, in _request_wrapper
    response = _request_wrapper(
               ^^^^^^^^^^^^^^^^^
  File "/Users/s3nik/Desktop/nlp-project-3/midi_caption_project/venv/lib/python3.11/site-packages/huggingface_hub/file_download.py", line 302, in _request_wrapper
    hf_raise_for_status(response)
  File "/Users/s3nik/Desktop/nlp-project-3/midi_caption_project/venv/lib/python3.11/site-packages/huggingface_hub/utils/_http.py", line 454, in hf_raise_for_status
    raise _format(RepositoryNotFoundError, message, response) from e
huggingface_hub.errors.RepositoryNotFoundError: 401 Client Error. (Request ID: Root=1-676a2373-1757ea2415b6c4c1406fd4be;c43b56b8-b504-440f-9708-fa26c06861bb)

Repository Not Found for url: https://huggingface.co/your-base-model/resolve/main/config.json.
Please make sure you specified the correct `repo_id` and `repo_type`.
If you are trying to access a private or gated repo, make sure you are authenticated.
Invalid username or password.

The above exception was the direct cause of the following exception:

Traceback (most recent call last):
  File "/Users/s3nik/Desktop/nlp-project-3/midi_caption_project/src/scripts/run_sweep.py", line 12, in train_function
    train_model(
  File "/Users/s3nik/Desktop/nlp-project-3/midi_caption_project/src/training/trainer.py", line 202, in train_model
    raise e
  File "/Users/s3nik/Desktop/nlp-project-3/midi_caption_project/src/training/trainer.py", line 180, in train_model
    model = AutoModelForCausalLM.from_pretrained("your-base-model")
            ^^^^^^^^^^^^^^^^^^^^^^^^^^^^^^^^^^^^^^^^^^^^^^^^^^^^^^^
  File "/Users/s3nik/Desktop/nlp-project-3/midi_caption_project/venv/lib/python3.11/site-packages/transformers/models/auto/auto_factory.py", line 488, in from_pretrained
    resolved_config_file = cached_file(
                           ^^^^^^^^^^^^
  File "/Users/s3nik/Desktop/nlp-project-3/midi_caption_project/venv/lib/python3.11/site-packages/transformers/utils/hub.py", line 410, in cached_file
    raise EnvironmentError(
OSError: your-base-model is not a local folder and is not a valid model identifier listed on 'https://huggingface.co/models'
If this is a private repository, make sure to pass a token having permission to this repo either by logging in with `huggingface-cli login` or by passing `token=<your_token>`
