Starting training run with config:
Traceback (most recent call last):
  File "/Users/s3nik/Desktop/nlp-project-3/midi_caption_project/venv/lib/python3.11/site-packages/wandb/sdk/wandb_config.py", line 165, in __getattr__
    return self.__getitem__(key)
           ^^^^^^^^^^^^^^^^^^^^^
  File "/Users/s3nik/Desktop/nlp-project-3/midi_caption_project/venv/lib/python3.11/site-packages/wandb/sdk/wandb_config.py", line 130, in __getitem__
    return self._items[key]
           ~~~~~~~~~~~^^^^^
KeyError: 'learning_rate'

The above exception was the direct cause of the following exception:

Traceback (most recent call last):
  File "/Users/s3nik/Desktop/nlp-project-3/midi_caption_project/src/scripts/run_sweep.py", line 36, in <module>
    main()
  File "/Users/s3nik/Desktop/nlp-project-3/midi_caption_project/src/scripts/run_sweep.py", line 16, in main
    print(f"Learning rate: {config.learning_rate}")
                            ^^^^^^^^^^^^^^^^^^^^
  File "/Users/s3nik/Desktop/nlp-project-3/midi_caption_project/venv/lib/python3.11/site-packages/wandb/sdk/wandb_config.py", line 167, in __getattr__
    raise AttributeError(
AttributeError: <class 'wandb.sdk.wandb_config.Config'> object has no attribute 'learning_rate'
